[2018-10-30 23:43:46,288] WARNING in config: Galeries Ponthé starting in DEV mode
[2018-10-30 23:51:24,825] WARNING in config: Galeries Ponthé starting in DEV mode
[2018-10-30 23:53:47,790] ERROR in app: Exception on /index [GET]
Traceback (most recent call last):
  File "/home/philippe/virtenvs/ponthe/lib/python3.6/site-packages/flask/app.py", line 2292, in wsgi_app
    response = self.full_dispatch_request()
  File "/home/philippe/virtenvs/ponthe/lib/python3.6/site-packages/flask/app.py", line 1815, in full_dispatch_request
    rv = self.handle_user_exception(e)
  File "/home/philippe/virtenvs/ponthe/lib/python3.6/site-packages/flask/app.py", line 1718, in handle_user_exception
    reraise(exc_type, exc_value, tb)
  File "/home/philippe/virtenvs/ponthe/lib/python3.6/site-packages/flask/_compat.py", line 35, in reraise
    raise value
  File "/home/philippe/virtenvs/ponthe/lib/python3.6/site-packages/flask/app.py", line 1813, in full_dispatch_request
    rv = self.dispatch_request()
  File "/home/philippe/virtenvs/ponthe/lib/python3.6/site-packages/flask/app.py", line 1799, in dispatch_request
    return self.view_functions[rule.endpoint](**req.view_args)
  File "/home/philippe/Personnal/ponthe.enpc.org/web/app/ponthe/private/views.py", line 45, in index
    return render_events_template('index.html', categories=CategoryDAO.find_all())
  File "/home/philippe/Personnal/ponthe.enpc.org/web/app/ponthe/private/views.py", line 35, in render_events_template
    return render_template(template, top_menu_galleries_by_year=top_menu_galleries_by_year, **kwargs)
  File "/home/philippe/virtenvs/ponthe/lib/python3.6/site-packages/flask/templating.py", line 135, in render_template
    context, ctx.app)
  File "/home/philippe/virtenvs/ponthe/lib/python3.6/site-packages/flask/templating.py", line 117, in _render
    rv = template.render(context)
  File "/home/philippe/virtenvs/ponthe/lib/python3.6/site-packages/jinja2/asyncsupport.py", line 76, in render
    return original_render(self, *args, **kwargs)
  File "/home/philippe/virtenvs/ponthe/lib/python3.6/site-packages/jinja2/environment.py", line 1008, in render
    return self.environment.handle_exception(exc_info, True)
  File "/home/philippe/virtenvs/ponthe/lib/python3.6/site-packages/jinja2/environment.py", line 780, in handle_exception
    reraise(exc_type, exc_value, tb)
  File "/home/philippe/virtenvs/ponthe/lib/python3.6/site-packages/jinja2/_compat.py", line 37, in reraise
    raise value.with_traceback(tb)
  File "/home/philippe/Personnal/ponthe.enpc.org/web/app/ponthe/templates/index.html", line 1, in top-level template code
    {% extends "layout/layout.html" %}
  File "/home/philippe/Personnal/ponthe.enpc.org/web/app/ponthe/templates/layout/layout.html", line 102, in top-level template code
    {% block content %}
  File "/home/philippe/Personnal/ponthe.enpc.org/web/app/ponthe/templates/index.html", line 72, in block "content"
    <img src="{{ url_for('uploads', file_path=category.cover_image.file_path) }}">
  File "/home/philippe/virtenvs/ponthe/lib/python3.6/site-packages/jinja2/environment.py", line 430, in getattr
    return getattr(obj, attribute)
jinja2.exceptions.UndefinedError: 'ponthe.models.File object' has no attribute 'cover_image'
